<sdf version='1.6'>
  <model name='pioneer3dx'>
    <link name='base_link'>
      <pose frame=''>0 0 0 0 -0 0</pose>
      <inertial>
        <pose frame=''>-0.031599 0 0.044721 0 -0 0</pose>
        <mass>12.5001</mass>
        <inertia>
          <ixx>1.16257</ixx>
          <ixy>0</ixy>
          <ixz>0.038363</ixz>
          <iyy>1.25617</iyy>
          <iyz>0</iyz>
          <izz>1.21907</izz>
        </inertia>
      </inertial>
      <collision name='base_link_fixed_joint_lump__chassis_collision'>
        <pose frame=''>-0.045 0 0.148 0 -0 0</pose>
        <geometry>
          <mesh>
            <scale>1 1 1</scale>
            <uri>model://cadrl/meshes/p3dx/chassis.stl</uri>
          </mesh>
        </geometry>
        <surface>
          <contact>
            <ode/>
          </contact>
          <friction>
            <ode/>
          </friction>
        </surface>
      </collision>
      <collision name='base_link_fixed_joint_lump__laser_collision_1'>
        <pose frame=''>0.18 0 0.17 0 -0 0</pose>
        <geometry>
          <box>
            <size>0.1 0.1 0.1</size>
          </box>
        </geometry>
        <surface>
          <contact>
            <ode/>
          </contact>
          <friction>
            <ode/>
          </friction>
        </surface>
      </collision>
      <collision name='base_link_fixed_joint_lump__sonar_collision_2'>
        <pose frame=''>0.109 0 0.209 0 -0 0</pose>
        <geometry>
          <box>
            <size>0.01 0.01 0.01</size>
          </box>
        </geometry>
        <surface>
          <contact>
            <ode/>
          </contact>
          <friction>
            <ode/>
          </friction>
        </surface>
      </collision>
      <collision name='base_link_fixed_joint_lump__top_collision_3'>
        <pose frame=''>-0.045 0 0.234 0 -0 0</pose>
        <geometry>
          <mesh>
            <scale>1 1 1</scale>
            <uri>model://cadrl/meshes/p3dx/top.stl</uri>
          </mesh>
        </geometry>
        <surface>
          <contact>
            <ode/>
          </contact>
          <friction>
            <ode/>
          </friction>
        </surface>
      </collision>
      <visual name='base_link_fixed_joint_lump__chassis_visual_visual'>
        <pose frame=''>-0.045 0 0.148 0 -0 0</pose>
        <geometry>
          <mesh>
            <scale>1 1 1</scale>
            <uri>model://cadrl/meshes/p3dx/chassis.stl</uri>
          </mesh>
        </geometry>
        <material>
          <script>
            <name>Gazebo/Red</name>
            <uri>file://media/materials/scripts/gazebo.material</uri>
          </script>
        </material>
      </visual>
      <visual name='base_link_fixed_joint_lump__battery0_visual_visual_1'>
        <pose frame=''>-0.14 0 0.13 0 -0 0</pose>
        <geometry>
          <box>
            <size>0.151 0.065 0.094</size>
          </box>
        </geometry>
        <material>
          <script>
            <name>Gazebo/Black</name>
            <uri>file://media/materials/scripts/gazebo.material</uri>
          </script>
        </material>
      </visual>
      <visual name='base_link_fixed_joint_lump__laser_visual_2'>
        <pose frame=''>0.18 0 0.17 0 -0 0</pose>
        <geometry>
          <mesh>
            <scale>1 1 1</scale>
            <uri>model://cadrl/meshes/laser/hokuyo.dae</uri>
          </mesh>
        </geometry>
        <material>
          <script>
            <uri>__default__</uri>
            <name>__default__</name>
          </script>
        </material>
      </visual>
      <visual name='base_link_fixed_joint_lump__front_sonar_vis_visual_3'>
        <pose frame=''>0.109 0 0.209 0 -0 0</pose>
        <geometry>
          <mesh>
            <scale>1 1 1</scale>
            <uri>model://cadrl/meshes/p3dx/back_sonar.stl</uri>
          </mesh>
        </geometry>
      </visual>
      <visual name='base_link_fixed_joint_lump__top_visual_4'>
        <pose frame=''>-0.045 0 0.234 0 -0 0</pose>
        <geometry>
          <mesh>
            <scale>1 1 1</scale>
            <uri>model://cadrl/meshes/p3dx/top.stl</uri>
          </mesh>
        </geometry>
        <material>
          <script>
            <name>Gazebo/Black</name>
            <uri>file://media/materials/scripts/gazebo.material</uri>
          </script>
        </material>
      </visual>
      <velocity_decay/>
      <velocity_decay/>
      <velocity_decay/>
      <sensor name='laser' type='ray'>
        <ray>
          <scan>
            <horizontal>
              <resolution>1</resolution>
              <max_angle>1.57</max_angle>
              <min_angle>-1.57</min_angle>
              <samples>180</samples>
            </horizontal>
          </scan>
          <range>
            <min>0.08</min>
            <max>5</max>
            <resolution>0.01</resolution>
          </range>
        </ray>
        <plugin name='laser' filename='libgazebo_ros_laser.so'>
          <robotNamespace/>
          <topicName>laser/scan</topicName>
          <frameName>laser</frameName>
        </plugin>
        <always_on>1</always_on>
        <update_rate>30</update_rate>
        <visualize>1</visualize>
        <pose frame=''>0.18 0 0.17 0 -0 0</pose>
      </sensor>
      <sensor name='bumper' type='contact'>
        <contact>
          <collision>base_link_fixed_joint_lump__laser_collision_1</collision>
          <topic>__default_topic__</topic>
        </contact>
        <plugin name='bumper' filename='libgazebo_ros_bumper.so'>
          <robotNamespace/>
          <topicName>laser/bumper</topicName>
          <frameName>laser</frameName>
        </plugin>
        <always_on>1</always_on>
        <update_rate>30</update_rate>
        <visualize>1</visualize>
        <pose frame=''>0.18 0 0.17 0 -0 0</pose>
      </sensor>
      <velocity_decay/>
      <gravity>1</gravity>
      <velocity_decay/>
      <self_collide>0</self_collide>
    </link>
    <link name='swivel'>
      <pose frame=''>-0.185 0 0.055 0 -0 0</pose>
      <inertial>
        <pose frame=''>0 0 0 0 -0 0</pose>
        <mass>0.1</mass>
        <inertia>
          <ixx>0.01</ixx>
          <ixy>0</ixy>
          <ixz>0</ixz>
          <iyy>0.01</iyy>
          <iyz>0</iyz>
          <izz>0.01</izz>
        </inertia>
      </inertial>
      <collision name='swivel_collision'>
        <pose frame=''>0 0 0 0 -0 0</pose>
        <geometry>
          <box>
            <size>0.01 0.01 0.01</size>
          </box>
        </geometry>
        <surface>
          <contact>
            <ode/>
          </contact>
          <friction>
            <ode/>
          </friction>
        </surface>
      </collision>
      <visual name='swivel_fixed_joint_lump__base_visual_visual'>
        <pose frame=''>0 0 0 0 -0 0</pose>
        <geometry>
          <mesh>
            <scale>1 1 1</scale>
            <uri>model://cadrl/meshes/p3dx/swivel.stl</uri>
          </mesh>
        </geometry>
      </visual>
      <gravity>1</gravity>
      <velocity_decay/>
      <self_collide>0</self_collide>
    </link>
    <joint name='chassis_swivel_joint' type='revolute'>
      <child>swivel</child>
      <parent>base_link</parent>
      <axis>
        <xyz>0 0 1</xyz>
        <limit>
          <lower>-1e+16</lower>
          <upper>1e+16</upper>
        </limit>
        <dynamics>
          <spring_reference>0</spring_reference>
          <spring_stiffness>0</spring_stiffness>
        </dynamics>
        <use_parent_model_frame>1</use_parent_model_frame>
      </axis>
    </joint>
    <link name='center_wheel'>
      <pose frame=''>-0.211 0 0.039 0 -0 0</pose>
      <inertial>
        <pose frame=''>-0.000318 0 -9.1e-05 0 -0 0</pose>
        <mass>0.11</mass>
        <inertia>
          <ixx>0.0248235</ixx>
          <ixy>-0.00142347</ixy>
          <ixz>0.00100543</ixz>
          <iyy>0.0304364</iyy>
          <iyz>-8.54693e-06</iyz>
          <izz>0.0235281</izz>
        </inertia>
      </inertial>
      <collision name='center_wheel_collision'>
        <pose frame=''>0 0 0 -1.5708 0 0</pose>
        <geometry>
          <cylinder>
            <length>0.01</length>
            <radius>0.0375</radius>
          </cylinder>
        </geometry>
        <surface>
          <contact>
            <ode/>
          </contact>
          <friction>
            <ode/>
          </friction>
        </surface>
      </collision>
      <collision name='center_wheel_fixed_joint_lump__center_hubcap_collision_1'>
        <pose frame=''>-0.0035 0 -0.001 0 -0 0</pose>
        <geometry>
          <box>
            <size>0.01 0.01 0.01</size>
          </box>
        </geometry>
        <surface>
          <contact>
            <ode/>
          </contact>
          <friction>
            <ode/>
          </friction>
        </surface>
      </collision>
      <visual name='center_wheel_fixed_joint_lump__base_visual_visual'>
        <pose frame=''>0 0 0 0 -0 0</pose>
        <geometry>
          <mesh>
            <scale>1 1 1</scale>
            <uri>model://cadrl/meshes/p3dx/center_wheel.stl</uri>
          </mesh>
        </geometry>
      </visual>
      <visual name='center_wheel_fixed_joint_lump__base_visual_visual_1'>
        <pose frame=''>-0.0035 0 -0.001 0 -0 0</pose>
        <geometry>
          <mesh>
            <scale>1 1 1</scale>
            <uri>model://cadrl/meshes/p3dx/center_hubcap.stl</uri>
          </mesh>
        </geometry>
      </visual>
      <velocity_decay/>
      <gravity>1</gravity>
      <velocity_decay/>
      <self_collide>0</self_collide>
    </link>
    <joint name='swivel_wheel_joint' type='revolute'>
      <child>center_wheel</child>
      <parent>swivel</parent>
      <axis>
        <xyz>0 1 0</xyz>
        <limit>
          <lower>-1e+16</lower>
          <upper>1e+16</upper>
        </limit>
        <dynamics>
          <spring_reference>0</spring_reference>
          <spring_stiffness>0</spring_stiffness>
        </dynamics>
        <use_parent_model_frame>1</use_parent_model_frame>
      </axis>
    </joint>
    <link name='left_hub'>
      <pose frame=''>0 -0.15 0.09 0 -0 0</pose>
      <inertial>
        <pose frame=''>0 0 0 0 -0 0</pose>
        <mass>0.51</mass>
        <inertia>
          <ixx>0.0248235</ixx>
          <ixy>0</ixy>
          <ixz>0</ixz>
          <iyy>0.0304363</iyy>
          <iyz>0</iyz>
          <izz>0.023528</izz>
        </inertia>
      </inertial>
      <collision name='left_hub_collision'>
        <pose frame=''>0 0 0 0 -0 0</pose>
        <geometry>
          <box>
            <size>0.01 0.01 0.01</size>
          </box>
        </geometry>
        <surface>
          <contact>
            <ode/>
          </contact>
          <friction>
            <ode/>
          </friction>
        </surface>
      </collision>
      <collision name='left_hub_fixed_joint_lump__left_wheel_collision_1'>
        <pose frame=''>0 0 0 -1.5708 0 0</pose>
        <geometry>
          <cylinder>
            <length>0.01</length>
            <radius>0.09</radius>
          </cylinder>
        </geometry>
        <surface>
          <contact>
            <ode/>
          </contact>
          <friction>
            <ode/>
          </friction>
        </surface>
      </collision>
      <visual name='left_hub_fixed_joint_lump__base_visual_visual'>
        <pose frame=''>0 0 0 0 -0 0</pose>
        <geometry>
          <mesh>
            <scale>1 1 1</scale>
            <uri>model://cadrl/meshes/p3dx/left_hubcap.stl</uri>
          </mesh>
        </geometry>
      </visual>
      <visual name='left_hub_fixed_joint_lump__base_visual_visual_1'>
        <pose frame=''>0 0 0 0 -0 0</pose>
        <geometry>
          <mesh>
            <scale>1 1 1</scale>
            <uri>model://cadrl/meshes/p3dx/left_wheel.stl</uri>
          </mesh>
        </geometry>
      </visual>
      <velocity_decay/>
      <gravity>1</gravity>
      <velocity_decay/>
      <self_collide>0</self_collide>
    </link>
    <joint name='left_hub_joint' type='revolute'>
      <child>left_hub</child>
      <parent>base_link</parent>
      <axis>
        <xyz>0 1 0</xyz>
        <limit>
          <lower>-1e+16</lower>
          <upper>1e+16</upper>
        </limit>
        <dynamics>
          <spring_reference>0</spring_reference>
          <spring_stiffness>0</spring_stiffness>
        </dynamics>
        <use_parent_model_frame>1</use_parent_model_frame>
      </axis>
    </joint>
    <link name='right_hub'>
      <pose frame=''>0 0.15 0.09 0 -0 0</pose>
      <inertial>
        <pose frame=''>0 0 0 0 -0 0</pose>
        <mass>0.51</mass>
        <inertia>
          <ixx>0.0248235</ixx>
          <ixy>0</ixy>
          <ixz>0</ixz>
          <iyy>0.0304363</iyy>
          <iyz>0</iyz>
          <izz>0.023528</izz>
        </inertia>
      </inertial>
      <collision name='right_hub_collision'>
        <pose frame=''>0 0 0 0 -0 0</pose>
        <geometry>
          <box>
            <size>0.01 0.01 0.01</size>
          </box>
        </geometry>
        <surface>
          <contact>
            <ode/>
          </contact>
          <friction>
            <ode/>
          </friction>
        </surface>
      </collision>
      <collision name='right_hub_fixed_joint_lump__right_wheel_collision_1'>
        <pose frame=''>0 0 0 -1.5708 0 0</pose>
        <geometry>
          <cylinder>
            <length>0.01</length>
            <radius>0.09</radius>
          </cylinder>
        </geometry>
        <surface>
          <contact>
            <ode/>
          </contact>
          <friction>
            <ode/>
          </friction>
        </surface>
      </collision>
      <visual name='right_hub_fixed_joint_lump__base_visual_visual'>
        <pose frame=''>0 0 0 0 -0 0</pose>
        <geometry>
          <mesh>
            <scale>1 1 1</scale>
            <uri>model://cadrl/meshes/p3dx/right_hubcap.stl</uri>
          </mesh>
        </geometry>
      </visual>
      <visual name='right_hub_fixed_joint_lump__base_visual_visual_1'>
        <pose frame=''>0 0 0 0 -0 0</pose>
        <geometry>
          <mesh>
            <scale>1 1 1</scale>
            <uri>model://cadrl/meshes/p3dx/right_wheel.stl</uri>
          </mesh>
        </geometry>
      </visual>
      <velocity_decay/>
      <gravity>1</gravity>
      <velocity_decay/>
      <self_collide>0</self_collide>
    </link>
    <joint name='right_hub_joint' type='revolute'>
      <child>right_hub</child>
      <parent>base_link</parent>
      <axis>
        <xyz>0 1 0</xyz>
        <limit>
          <lower>-1e+16</lower>
          <upper>1e+16</upper>
        </limit>
        <dynamics>
          <spring_reference>0</spring_reference>
          <spring_stiffness>0</spring_stiffness>
        </dynamics>
        <use_parent_model_frame>1</use_parent_model_frame>
      </axis>
    </joint>
    <plugin name='differential_drive_controller' filename='libgazebo_ros_diff_drive.so'>
      <rosDebugLevel>Debug</rosDebugLevel>
      <robotNamespace/>
      <publishWheelTF>false</publishWheelTF>
      <publishWheelJointState>true</publishWheelJointState>
      <alwaysOn>true</alwaysOn>
      <leftJoint>left_hub_joint</leftJoint>
      <rightJoint>right_hub_joint</rightJoint>
      <wheelSeparation>0.3</wheelSeparation>
      <wheelDiameter>0.18</wheelDiameter>
      <wheelTorque>20</wheelTorque>
      <wheelAcceleration>1.8</wheelAcceleration>
      <commandTopic>cmd_vel</commandTopic>
      <odometryTopic>odom</odometryTopic>
      <odometryFrame>odom</odometryFrame>
      <odometrySource>world</odometrySource>
      <robotBaseFrame>base_link</robotBaseFrame>
      <updateRate>10.0</updateRate>
    </plugin>
    <static>0</static>
    <plugin name='joint_state_publisher' filename='libgazebo_ros_joint_state_publisher.so'>
      <robotNamespace/>
      <jointName>chassis_swivel_joint, swivel_wheel_joint, left_hub_joint, right_hub_joint</jointName>
      <updateRate>10.0</updateRate>
      <alwaysOn>true</alwaysOn>
    </plugin>
  </model>
</sdf>
